// NOTE: I'd love to not have to deal with this, but...
//       it seems that unhandled exceptions (at least in Dartium) crash things
//       http://dartbug.com/3734
class SendValuePort<TInput, TOutput> {
  final Func1<TInput, TOutput> _func;

  SendValuePort(this._func) {
    port.receive((TInput value, SendPort reply) {
      FutureValueResult<TOutput> _message;
      try {
        final TOutput output = _func(value);
        _message = new FutureValueResult<TOutput>(output);
      } catch(final ex) {
        // TODO: I'd love to use real exceptions here
        // but they blow up over the wire
        // so: to string!
        final String exString = ex.toString();
        _message = new FutureValueResult<TOutput>.exception(exString);
      }

      final map = _message.toMap();
      reply.send(map);
    });
  }
}
